<robot name="onshape">

  <link name="palm_lower">
    <visual>
      <origin xyz="-0.020095249652862544332 -0.025757756134899473244 -0.034722403578460216134" rpy="0 -0 0" />
      <geometry>
        <mesh filename="palm_lower_left.stl"/>
      </geometry>
      <material name="palm_lower_material">
        <color rgba="0.2 0.2 0.2 1.0"/>
      </material>
    </visual>
    <collision>
      <origin xyz="-0.020095249652862544332 -0.025757756134899473244 -0.034722403578460216134" rpy="0 -0 0" />
      <geometry>
        <mesh filename="palm_lower_left.stl" />
      </geometry>
    </collision>
    <inertial>
      <origin xyz="0 0 0" rpy="0 0 0"/>
      <mass value="0.237" />
      <inertia ixx="0.000354094" ixy="-0.000001193"  ixz="-0.000002445" iyy="0.000260915" iyz="-0.000002905" izz="0.000529257" />
    </inertial>
  </link>

  <link name="mcp_joint_1">
    <visual>
      <origin xyz="0.0084069022611744960438 0.0077662438597169954416 0.014657354985032912051" rpy="1.6375789613220999807e-15 -1.0210473302491019535e-30 1.7177968783327987474e-31" />
      <geometry>
        <mesh filename="mcp_joint.stl"/>
      </geometry>
      <material name="mcp_joint_material">
        <color rgba="0.2 0.2 0.2 1.0"/>
      </material>
    </visual>
    <collision>
      <origin xyz="0.0084069022611744960438 0.0077662438597169954416 0.014657354985032912051" rpy="1.6375789613220999807e-15 -1.0210473302491019535e-30 1.7177968783327987474e-31" />
      <geometry>
        <mesh filename="mcp_joint.stl" />
      </geometry>
    </collision>
    <inertial>
      <origin xyz="0 0 0" rpy="0 0 0"/>
        <mass value="0.044" />
      <inertia ixx="0.000011499" ixy="0.000003049"  ixz="0.000000121" iyy="0.000007796" iyz="0.000000112" izz="0.000014759" />
    </inertial>
  </link>

  <link name="pip_1">
    <visual>
      <origin xyz="0.0096433630922713280131 0.00029999999999998951117 0.00078403401041737645627" rpy="-1.570796326794896558 -1.570796326794896336 0" />
      <geometry>
        <mesh filename="pip.stl"/>
      </geometry>
      <material name="pip_material">
        <color rgba="0.2 0.2 0.2 1.0"/>
      </material>
    </visual>
    <collision>
      <origin xyz="0.0096433630922713280131 0.00029999999999998951117 0.00078403401041737645627" rpy="-1.570796326794896558 -1.570796326794896336 0" />
      <geometry>
        <mesh filename="pip.stl" />
      </geometry>
    </collision>
    <inertial>
      <origin xyz="0 0 0" rpy="0 0 0"/>
      <mass value="0.032" />
      <inertia ixx="0.000004798" ixy="0.000000012"  ixz="0.000000004" iyy="0.000002862" iyz="0.000000011" izz="0.000004234" />
    </inertial>
  </link>

  <link name="dip_1">
    <visual>
      <origin xyz="0.021133352895225002849 -0.0084321191467048792201 0.0097850881620952408213" rpy="-3.141592653589793116 4.5075111242164408299e-32 4.4395481053923607589e-32" />
      <geometry>
        <mesh filename="dip.stl"/>
      </geometry>
      <material name="dip_material">
        <color rgba="0.2 0.2 0.2 1.0"/>
      </material>
    </visual>
    <collision>
      <origin xyz="0.021133352895225002849 -0.0084321191467048792201 0.0097850881620952408213" rpy="-3.141592653589793116 4.5075111242164408299e-32 4.4395481053923607589e-32" />
      <geometry>
        <mesh filename="dip.stl" />
      </geometry>
    </collision>
    <inertial>
      <origin xyz="0 0 0" rpy="0 0 0"/>
      <mass value="0.037" />
      <inertia ixx="0.000005542" ixy="-0.000000607"  ixz="-0.000000017" iyy="0.000005727" iyz="-0.000000023" izz="0.000006682" />
    </inertial>
  </link>

  <link name="fingertip_1">
    <visual>
      <origin xyz="0.013286424108533503169 -0.0061142383865419869249 0.014499999999999497666" rpy="3.141592653589793116 1.1993117970061734707e-33 4.4395481053923607589e-32" />
      <geometry>
        <mesh filename="fingertip.stl"/>
      </geometry>
      <material name="fingertip_material">
        <color rgba="0.2 0.2 0.2 1.0"/>
      </material>
    </visual>
    <collision>
      <origin xyz="0.013286424108533503169 -0.0061142383865419869249 0.014499999999999497666" rpy="3.141592653589793116 1.1993117970061734707e-33 4.4395481053923607589e-32" />
      <geometry>
        <mesh filename="fingertip.stl" />
      </geometry>
    </collision>
    <inertial>
      <origin xyz="0 0 0" rpy="0 0 0"/>
      <mass value="0.016" />
      <inertia ixx="0.000003368" ixy="0.000000115"  ixz="0" iyy="0.000001556" iyz="0" izz="0.000002863" />
    </inertial>
  </link>

  <joint name="finger_joint_0" type="revolute">
    <origin xyz="-0.012200000000000007713 0.038099999999999994982 0.014500000000000000736" rpy="-1.570796326794896558 -1.0065212660796336576e-15 1.5707963267948943376" />
    <parent link="mcp_joint_1" />
    <child link="pip_1" />
    <axis xyz="0 0 -1"/>
    <limit effort="0.95" velocity="8.48" lower = "-1.047" upper = "1.047"/>
    <joint_properties friction="0.0"/>
  </joint>

  <joint name="finger_joint_1" type="revolute">
    <origin xyz="-0.0070952496528625457958 0.096057756134899472233 -0.01872240357846021927" rpy="1.5707963267948950037 1.5707963267948945596 0" />
    <parent link="palm_lower" />
    <child link="mcp_joint_1" />
    <axis xyz="0 0 -1"/>
    <limit effort="0.95" velocity="8.48" lower = "-0.314" upper = "2.23"/>
    <joint_properties friction="0.0"/>
  </joint>

  <joint name="finger_joint_2" type="revolute">
    <origin xyz="0.01499999999999996822 0.014299999999999904801 -0.012999999999999824196" rpy="1.5707963267948958919 -1.570796326794896336 0" />
    <parent link="pip_1" />
    <child link="dip_1" />
    <axis xyz="0 0 -1"/>
    <limit effort="0.95" velocity="8.48" lower = "-0.506" upper = "1.885"/>
    <joint_properties friction="0.0"/>
  </joint>

  <joint name="finger_joint_3" type="revolute">
    <origin xyz="-4.0880582495572692636e-09 -0.036100004210367367397 0.00020000000000007858714" rpy="4.5935029425113685044e-17 -2.8730071914463794583e-16 4.4395481053923607589e-32" />
    <parent link="dip_1" />
    <child link="fingertip_1" />
    <axis xyz="0 0 -1"/>
    <limit effort="0.95" velocity="8.48" lower = "-0.366" upper = "2.042"/>
    <joint_properties friction="0.0"/>
  </joint>

  <link name="mcp_joint_2">
    <visual>
      <origin xyz="0.0084069022611744960438 0.0077662438597169954416 0.014657354985032913786" rpy="1.6375789613220999807e-15 -1.0076465469034000467e-30 2.1209300131419907151e-61" />
      <geometry>
        <mesh filename="mcp_joint.stl"/>
      </geometry>
      <material name="mcp_joint_material">
        <color rgba="0.2 0.2 0.2 1.0"/>
      </material>
    </visual>
    <collision>
      <origin xyz="0.0084069022611744960438 0.0077662438597169954416 0.014657354985032913786" rpy="1.6375789613220999807e-15 -1.0076465469034000467e-30 2.1209300131419907151e-61" />
      <geometry>
        <mesh filename="mcp_joint.stl" />
      </geometry>
    </collision>
    <inertial>
      <origin xyz="0 0 0" rpy="0 0 0"/>
      <mass value="0.044" />
      <inertia ixx="0.000011499" ixy="0.000003049"  ixz="0.000000121" iyy="0.000007796" iyz="0.000000112" izz="0.000014759" />
    </inertial>
  </link>

  <link name="pip_2">
    <visual>
      <origin xyz="0.0096433630922713280131 0.00029999999999999471534 0.00078403401041737645627" rpy="-1.570796326794896558 -1.570796326794896336 0" />
      <geometry>
        <mesh filename="pip.stl"/>
      </geometry>
      <material name="pip_material">
        <color rgba="0.2 0.2 0.2 1.0"/>
      </material>
    </visual>
    <collision>
      <origin xyz="0.0096433630922713280131 0.00029999999999999471534 0.00078403401041737645627" rpy="-1.570796326794896558 -1.570796326794896336 0" />
      <geometry>
        <mesh filename="pip.stl" />
      </geometry>
    </collision>
    <inertial>
      <origin xyz="0 0 0" rpy="0 0 0"/>
      <mass value="0.032" />
      <inertia ixx="0.000004798" ixy="0.000000012"  ixz="0.000000004" iyy="0.000002862" iyz="0.000000011" izz="0.000004234" />
    </inertial>
  </link>

  <link name="dip_2">
    <visual>
      <origin xyz="0.021133352895225002849 -0.0084321191467048653423 0.0097850881620952373519" rpy="-3.141592653589793116 2.1146933785271955805e-32 1.4408183216511868558e-31" />
      <geometry>
        <mesh filename="dip.stl"/>
      </geometry>
      <material name="dip_material">
        <color rgba="0.2 0.2 0.2 1.0"/>
      </material>
    </visual>
    <collision>
      <origin xyz="0.021133352895225002849 -0.0084321191467048653423 0.0097850881620952373519" rpy="-3.141592653589793116 2.1146933785271955805e-32 1.4408183216511868558e-31" />
      <geometry>
        <mesh filename="dip.stl" />
      </geometry>
    </collision>
    <inertial>
      <origin xyz="0 0 0" rpy="0 0 0"/>
      <mass value="0.037" />
      <inertia ixx="0.000005542" ixy="-0.000000607"  ixz="-0.000000017" iyy="0.000005727" iyz="-0.000000023" izz="0.000006682" />
    </inertial>
  </link>

  <link name="fingertip_2">
    <visual>
      <origin xyz="0.01328642410853349623 -0.0061142383865420008027 0.014499999999999495931" rpy="3.141592653589793116 -4.3179597882835943107e-33 1.4408183216511868558e-31" />
      <geometry>
        <mesh filename="fingertip.stl"/>
      </geometry>
      <material name="fingertip_material">
        <color rgba="0.2 0.2 0.2 1.0"/>
      </material>
    </visual>
    <collision>
      <origin xyz="0.01328642410853349623 -0.0061142383865420008027 0.014499999999999495931" rpy="3.141592653589793116 -4.3179597882835943107e-33 1.4408183216511868558e-31" />
      <geometry>
        <mesh filename="fingertip.stl" />
      </geometry>
    </collision>
    <inertial>
      <origin xyz="0 0 0" rpy="0 0 0"/>
      <mass value="0.016" />
      <inertia ixx="0.000003368" ixy="0.000000115"  ixz="0" iyy="0.000001556" iyz="0" izz="0.000002863" />
    </inertial>
  </link>

  <joint name="finger_joint_4" type="revolute">
    <origin xyz="-0.012200000000000019856 0.038099999999999981104 0.01450000000000000594" rpy="-1.570796326794896558 -1.0065212760057939085e-15 1.5707963267948943376" />
    <parent link="mcp_joint_2" />
    <child link="pip_2" />
    <axis xyz="0 0 -1"/>
    <limit effort="0.95" velocity="8.48" lower = "-1.047" upper = "1.047"/>
    <joint_properties friction="0.0"/>
  </joint>

  <joint name="finger_joint_5" type="revolute">
    <origin xyz="-0.0070952496528625388569 0.05060775613 -0.018722403578460229678" rpy="1.570796326794896558 1.570796326794896558 0" />
    <parent link="palm_lower" />
    <child link="mcp_joint_2" />
    <axis xyz="0 0 -1"/>
    <limit effort="0.95" velocity="8.48" lower = "-0.314" upper = "2.23"/>
    <joint_properties friction="0.0"/>
  </joint>

  <joint name="finger_joint_6" type="revolute">
    <origin xyz="0.014999999999999975159 0.014300000000000000211 -0.013000000000000018485" rpy="1.5707963267948958919 -1.570796326794896336 0" />
    <parent link="pip_2" />
    <child link="dip_2" />
    <axis xyz="0 0 -1"/>
    <limit effort="0.95" velocity="8.48" lower = "-0.506" upper = "1.885"/>
    <joint_properties friction="0.0"/>
  </joint>

  <joint name="finger_joint_7" type="revolute">
    <origin xyz="1.0061396160665481148e-16 -0.036099999999999854428 0.00020000000000007858714" rpy="4.5935029425113654229e-17 -2.8730071914463794583e-16 1.4408183216511868558e-31" />
    <parent link="dip_2" />
    <child link="fingertip_2" />
    <axis xyz="0 0 -1"/>
    <limit effort="0.95" velocity="8.48" lower = "-0.366" upper = "2.042"/>
    <joint_properties friction="0.0"/>
  </joint>

  <link name="mcp_joint_3">
    <visual>
      <origin xyz="0.0084069022611744995133 0.0077662438597169963089 0.014657354985032913786" rpy="1.6375789613220999807e-15 -1.0059504988632626953e-30 5.729641584552035421e-32" />
      <geometry>
        <mesh filename="mcp_joint.stl"/>
      </geometry>
      <material name="mcp_joint_material">
        <color rgba="0.2 0.2 0.2 1.0"/>
      </material>
    </visual>
    <collision>
      <origin xyz="0.0084069022611744995133 0.0077662438597169963089 0.014657354985032913786" rpy="1.6375789613220999807e-15 -1.0059504988632626953e-30 5.729641584552035421e-32" />
      <geometry>
        <mesh filename="mcp_joint.stl" />
      </geometry>
    </collision>
    <inertial>
      <origin xyz="0 0 0" rpy="0 0 0"/>
      <mass value="0.044" />
      <inertia ixx="0.000011499" ixy="0.000003049"  ixz="0.000000121" iyy="0.000007796" iyz="0.000000112" izz="0.000014759" />
    </inertial>
  </link>

  <link name="pip_3">
    <visual>
      <origin xyz="0.0096433630922713314826 0.00029999999999998083755 0.00078403401041737645627" rpy="-1.570796326794896558 -1.570796326794896336 0" />
      <geometry>
        <mesh filename="pip.stl"/>
      </geometry>
      <material name="pip_material">
        <color rgba="0.2 0.2 0.2 1.0"/>
      </material>
    </visual>
    <collision>
      <origin xyz="0.0096433630922713314826 0.00029999999999998083755 0.00078403401041737645627" rpy="-1.570796326794896558 -1.570796326794896336 0" />
      <geometry>
        <mesh filename="pip.stl" />
      </geometry>
    </collision>
    <inertial>
      <origin xyz="0 0 0" rpy="0 0 0"/>
      <mass value="0.032" />
      <inertia ixx="0.000004798" ixy="0.000000012"  ixz="0.000000004" iyy="0.000002862" iyz="0.000000011" izz="0.000004234" />
    </inertial>
  </link>

  <link name="dip_3">
    <visual>
      <origin xyz="0.021133352895225006318 -0.0084321191467048653423 0.0097850881620952373519" rpy="-3.141592653589793116 -1.4095651113919093005e-33 1.5565411607615035382e-32" />
      <geometry>
        <mesh filename="dip.stl"/>
      </geometry>
      <material name="dip_material">
        <color rgba="0.2 0.2 0.2 1.0"/>
      </material>
    </visual>
    <collision>
      <origin xyz="0.021133352895225006318 -0.0084321191467048653423 0.0097850881620952373519" rpy="-3.141592653589793116 -1.4095651113919093005e-33 1.5565411607615035382e-32" />
      <geometry>
        <mesh filename="dip.stl" />
      </geometry>
    </collision>
    <inertial>
      <origin xyz="0 0 0" rpy="0 0 0"/>
      <mass value="0.037" />
      <inertia ixx="0.000005542" ixy="-0.000000607"  ixz="-0.000000017" iyy="0.000005727" iyz="-0.000000023" izz="0.000006682" />
    </inertial>
  </link>

  <link name="fingertip_3">
    <visual>
      <origin xyz="0.013286424108533501434 -0.0061142383865419869249 0.0144999999999994994" rpy="3.141592653589793116 8.6170716950575402125e-33 1.5565411607615035382e-32" />
      <geometry>
        <mesh filename="fingertip.stl"/>
      </geometry>
      <material name="fingertip_material">
        <color rgba="0.2 0.2 0.2 1.0"/>
      </material>
    </visual>
    <collision>
      <origin xyz="0.013286424108533501434 -0.0061142383865419869249 0.0144999999999994994" rpy="3.141592653589793116 8.6170716950575402125e-33 1.5565411607615035382e-32" />
      <geometry>
        <mesh filename="fingertip.stl" />
      </geometry>
    </collision>
    <inertial>
      <origin xyz="0 0 0" rpy="0 0 0"/>
      <mass value="0.016" />
      <inertia ixx="0.000003368" ixy="0.000000115"  ixz="0" iyy="0.000001556" iyz="0" izz="0.000002863" />
    </inertial>
  </link>

  <joint name="finger_joint_8" type="revolute">
    <origin xyz="-0.012200000000000004244 0.038100000000000001921 0.014499999999999999001" rpy="-1.570796326794896558 -1.0065212660796360242e-15 1.5707963267948943376" />
    <parent link="mcp_joint_3" />
    <child link="pip_3" />
    <axis xyz="0 0 -1"/>
    <limit effort="0.95" velocity="8.48" lower = "-1.047" upper = "1.047"/>
    <joint_properties friction="0.0"/>
  </joint>

  <joint name="finger_joint_9" type="revolute">
    <origin xyz="-0.0070952454426398371343 0.00515775613 -0.018722407666402932774" rpy="1.5707963267948950037 1.5707963267948945596 0" />
    <parent link="palm_lower" />
    <child link="mcp_joint_3" />
    <axis xyz="0 0 -1"/>
    <limit effort="0.95" velocity="8.48" lower = "-0.314" upper = "2.23"/>
    <joint_properties friction="0.0"/>
  </joint>

  <joint name="finger_joint_10" type="revolute">
    <origin xyz="0.014999999999999971689 0.014299999999999951639 -0.012999999999999959505" rpy="1.5707963267948958919 -1.570796326794896336 0" />
    <parent link="pip_3" />
    <child link="dip_3" />
    <axis xyz="0 0 -1"/>
    <limit effort="0.95" velocity="8.48" lower = "-0.506" upper = "1.885"/>
    <joint_properties friction="0.0"/>
  </joint>

  <joint name="finger_joint_11" type="revolute">
    <origin xyz="9.7144514654701197287e-17 -0.036099999999999868305 0.00020000000000007511769" rpy="4.5935029425113685044e-17 -2.8730071914463799514e-16 1.5565411607615035382e-32" />
    <parent link="dip_3" />
    <child link="fingertip_3" />
    <axis xyz="0 0 -1"/>
    <limit effort="0.95" velocity="8.48" lower = "-0.366" upper = "2.042"/>
    <joint_properties friction="0.0"/>
  </joint>

  <link name="mcp_joint_4">
    <visual>
      <origin xyz="-0.0053566369077286714317 0.0029999999999999991951 0.00078403401041737819099" rpy="-1.570796326794896558 -1.570796326794896336 0" />
      <geometry>
        <mesh filename="pip.stl"/>
      </geometry>
      <material name="pip_material">
        <color rgba="0.2 0.2 0.2 1.0"/>
      </material>
    </visual>
    <collision>
      <origin xyz="-0.0053566369077286714317 0.00029999999999999991951 0.00078403401041737819099" rpy="-1.570796326794896558 -1.570796326794896336 0" />
      <geometry>
        <mesh filename="pip.stl" />
      </geometry>
    </collision>
    <inertial>
      <origin xyz="0 0 0" rpy="0 0 0"/>
      <mass value="0.032" />
      <inertia ixx="0.000004798" ixy="0.000000012"  ixz="0.000000004" iyy="0.000002862" iyz="0.000000011" izz="0.000004234" />
    </inertial>
  </link>

  <link name="pip_4">
    <visual>
      <origin xyz="0.011961920770611186859 -5.3082538364890297089e-16 -0.015852648956664199681" rpy="1.570796326794896558 1.6050198443300152637e-46 -3.9204996250525192755e-59" />
      <geometry>
        <mesh filename="thumb_pip.stl"/>
      </geometry>
      <material name="thumb_pip_material">
        <color rgba="0.2 0.2 0.2 1.0"/>
      </material>
    </visual>
    <collision>
    <origin xyz="0.011961920770611186859 -5.3082538364890297089e-16 -0.015852648956664199681" rpy="1.570796326794896558 1.6050198443300152637e-46 -3.9204996250525192755e-59" />
      <geometry>
        <mesh filename="thumb_pip.stl" />
      </geometry>
    </collision>
    <inertial>
      <origin xyz="0 0 0" rpy="0 0 0"/>
      <mass value="0.003" />
      <inertia ixx="0.000000593" ixy="0"  ixz="0" iyy="0.000000549" iyz="0" izz="0.000000224" />
    </inertial>
  </link>

  <link name="dip_4">
    <visual>
      <origin xyz="0.043968715707239175439 0.057952952973709198625 -0.0086286764493694757122" rpy="1.9428902930940098942e-16 3.2751579226442200773e-15 1.1123758529657360012e-46" />
      <geometry>
        <mesh filename="thumb_dip.stl"/>
      </geometry>
      <material name="thumb_dip_material">
        <color rgba="0.2 0.2 0.2 1.0"/>
      </material>
    </visual>
    <collision>
      <origin xyz="0.043968715707239175439 0.057952952973709198625 -0.0086286764493694757122" rpy="1.9428902930940098942e-16 3.2751579226442200773e-15 1.1123758529657360012e-46" />
      <geometry>
        <mesh filename="thumb_dip.stl" />
      </geometry>
    </collision>
    <inertial>
      <origin xyz="0 0 0" rpy="0 0 0"/>
      <mass value="0.038" />
      <inertia ixx="0.000008474" ixy="0.000000241"  ixz="0.000000026" iyy="0.000003841" iyz="0.000000025" izz="0.000007679" />
    </inertial>
  </link>

  <link name="fingertip_4">
    <visual>
      <origin xyz="0.062559538462667388381 0.078459682911396988469 0.048992911807332215068" rpy="4.3790577010156367543e-47 -3.3306690738754701143e-16 1.2042408677791935383e-46" />
      <geometry>
        <mesh filename="thumb_fingertip.stl"/>
      </geometry>
      <material name="thumb_fingertip_material">
        <color rgba="0.2 0.2 0.2 1.0"/>
      </material>
    </visual>
    <collision>
      <origin xyz="0.062559538462667388381 0.078459682911396988469 0.048992911807332215068" rpy="4.3790577010156367543e-47 -3.3306690738754701143e-16 1.2042408677791935383e-46" />
      <geometry>
        <mesh filename="thumb_fingertip.stl" />
      </geometry>
    </collision>
    <inertial>
      <origin xyz="0 0 0" rpy="0 0 0"/>
      <mass value="0.049" />
      <inertia ixx="0.000020372" ixy="-0.000000489"  ixz="-0.00000003" iyy="0.000004336" iyz="-0.000000097" izz="0.000019845" />
    </inertial>
  </link>

  <joint name="finger_joint_12" type="revolute">
    <origin xyz="-0.069395249652862533996 0.0012422438651005258004 -0.021622403578460215601" rpy="-3.141592653589793116 -1.5707963267948956698 0" />
    <!-- <origin xyz="-0.069395249652862533996 -0.0012422438651005258004 -0.021622403578460215601" rpy="-8.2381766464939424156e-17 1.5707963267948956698 0" /> -->
    <parent link="palm_lower" />
    <child link="mcp_joint_4" />
    <axis xyz="0 0 -1"/>
    <limit effort="0.95" velocity="8.48" lower = "-0.349" upper = "2.094"/>
    <joint_properties friction="0.0"/>
  </joint>

  <joint name="finger_joint_13" type="revolute">
    <origin xyz="-2.7755575615628913511e-17 0.014300000000000005415 -0.013000000000000011546" rpy="1.5707963267948958919 -1.570796326794896336 0" />
    <!-- <origin xyz="-2.7755575615628913511e-17 0.014300000000000005415 -0.013000000000000011546" rpy="1.5707963267948958919 -1.570796326794896336 0" /> -->
    <parent link="mcp_joint_4" />
    <child link="pip_4" />
    <axis xyz="0 0 1"/>
    <limit effort="0.95" velocity="8.48" lower = "-0.47" upper = "2.443"/>
    <joint_properties friction="0.0"/>
  </joint>

  <joint name="finger_joint_14" type="revolute">
    <origin xyz="0 0.014499999999999966041 -0.017000000000000053263" rpy="-1.570796326794896558 1.6050198443300131245e-46 -1.9721522630516624601e-31" />
    <parent link="pip_4" />
    <child link="dip_4" />
    <axis xyz="0 0 -1"/>
    <limit effort="0.95" velocity="8.48" lower = "-1.20" upper = "1.90"/>
    <joint_properties friction="0.0"/>
  </joint>

  <joint name="finger_joint_15" type="revolute">
    <origin xyz="-1.249000902703301108e-16 0.046599999999999863753 0.00019999999999997710581" rpy="1.5063958491491781023e-44 5.4234187233935260503e-31 3.141592653589793116" />
    <parent link="dip_4" />
    <child link="fingertip_4" />
    <axis xyz="0 0 -1"/>
    <limit effort="0.95" velocity="8.48" lower = "-1.34" upper = "1.88"/>
    <joint_properties friction="0.0"/>
  </joint>

<link name="realtip">
    <visual>
        <origin xyz="0 0 0" rpy="0 0 0" />
        <geometry>
            <sphere radius="0.005"/>
        </geometry>
        <material name="ball_material">
            <color rgba="1 0 0 1"/>
        </material>
    </visual>
    <collision>
        <origin xyz="0 0 0" rpy="0 0 0" />
        <geometry>
            <sphere radius="0.005"/>
        </geometry>
    </collision>
    <inertial>
        <origin xyz="0 0 0" rpy="0 0 0"/>
        <mass value="0.1"/>
        <inertia ixx="0.000025" ixy="0" ixz="0" iyy="0.000025" iyz="0" izz="0.000025"/>
    </inertial>
</link>

<joint name="16" type="fixed">
<origin xyz="0.0 -0.09 0.015" rpy="4.5935029425113685044e-17 -2.8730071914463794583e-16 4.4395481053923607589e-32" />
<parent link="fingertip_1" />
<child link="realtip" />
<axis xyz="0 0 -1"/>
<limit effort="0.95" velocity="8.48" lower = "-0.366" upper = "2.042"/>
<joint_properties friction="0.0"/>
</joint>

<link name="realtip_2">
    <visual>
        <origin xyz="0 0 0" rpy="0 0 0" />
        <geometry>
            <sphere radius="0.005"/>
        </geometry>
        <material name="ball_material">
            <color rgba="1 0 0 1"/>
        </material>
    </visual>
    <collision>
        <origin xyz="0 0 0" rpy="0 0 0" />
        <geometry>
            <sphere radius="0.005"/>
        </geometry>
    </collision>
    <inertial>
        <origin xyz="0 0 0" rpy="0 0 0"/>
        <mass value="0.1"/>
        <inertia ixx="0.000025" ixy="0" ixz="0" iyy="0.000025" iyz="0" izz="0.000025"/>
    </inertial>
</link>

<joint name="17" type="fixed">
<origin xyz="0.0 -0.09 0.015" rpy="4.5935029425113685044e-17 -2.8730071914463794583e-16 4.4395481053923607589e-32" />
<parent link="fingertip_2" />
<child link="realtip_2" />
<axis xyz="0 0 -1"/>
<limit effort="0.95" velocity="8.48" lower = "-0.366" upper = "2.042"/>
<joint_properties friction="0.0"/>
</joint>


<link name="realtip_3">
    <visual>
        <origin xyz="0 0 0" rpy="0 0 0" />
        <geometry>
            <sphere radius="0.005"/>
        </geometry>
        <material name="ball_material">
            <color rgba="0 1 0 1"/>
        </material>
    </visual>
    <collision>
        <origin xyz="0 0 0" rpy="0 0 0" />
        <geometry>
            <sphere radius="0.005"/>
        </geometry>
    </collision>
    <inertial>
        <origin xyz="0 0 0" rpy="0 0 0"/>
        <mass value="0.1"/>
        <inertia ixx="0.000025" ixy="0" ixz="0" iyy="0.000025" iyz="0" izz="0.000025"/>
    </inertial>
</link>

<joint name="18" type="fixed">
<origin xyz="0.0 -0.09 0.015" rpy="4.5935029425113685044e-17 -2.8730071914463794583e-16 4.4395481053923607589e-32" />
<parent link="fingertip_3" />
<child link="realtip_3" />
<axis xyz="0 0 -1"/>
<limit effort="0.95" velocity="8.48" lower = "-0.366" upper = "2.042"/>
<joint_properties friction="0.0"/>
</joint>


<link name="realtip_4">
    <visual>
        <origin xyz="0 0 0" rpy="0 0 0" />
        <geometry>
            <sphere radius="0.005"/>
        </geometry>
        <material name="ball_material">
            <color rgba="0 1 0 1"/>
        </material>
    </visual>
    <collision>
        <origin xyz="0 0 0" rpy="0 0 0" />
        <geometry>
            <sphere radius="0.005"/>
        </geometry>
    </collision>
    <inertial>
        <origin xyz="0 0 0" rpy="0 0 0"/>
        <mass value="0.1"/>
        <inertia ixx="0.000025" ixy="0" ixz="0" iyy="0.000025" iyz="0" izz="0.000025"/>
    </inertial>
</link>

<joint name="19" type="fixed">
<origin xyz="0.0 -0.09 -0.015" rpy="4.5935029425113685044e-17 -2.8730071914463794583e-16 4.4395481053923607589e-32" />
<parent link="fingertip_4" />
<child link="realtip_4" />
<axis xyz="0 0 -1"/>
<limit effort="0.95" velocity="8.48" lower = "-0.366" upper = "2.042"/>
<joint_properties friction="0.0"/>
</joint>

</robot>
